<?xml version='1.0'?>
<sdf version="1.4">
    <model name="Rover">
        <pose>0 0 0.5 0 0 0</pose>
        <static>false</static>
        <link name="body">
            <gravity>false</gravity>
            <collision name="body_collision">
                <geometry>
                    <box>
                        <size>0.5 0.5 0.25</size>
                    </box>
                </geometry>
            </collision>
            <visual name="body_visual">
                <geometry>
                    <box>
                        <size>0.5 0.5 0.25</size>
                    </box>
                </geometry>
            </visual>
        </link>

        <link name="left_rocker">
            <gravity>false</gravity>
            <pose>0.25 -0.7 -0.4 1.571 0 1.571</pose>
            <inertial>
                <pose>0.7 0.35 0 0 0 0</pose>
            </inertial>
            <collision name="left_rocker_collision">
                <geometry>
                    <mesh>
                        <uri>model://rover/meshes/Rocker_Type_1.STL</uri>
                        <scale>0.001 0.001 0.001</scale>
                    </mesh>
                </geometry>
            </collision>
            <visual name="left_rocker_visual">
                <geometry>
                    <mesh>
                        <uri>model://rover/meshes/Rocker_Type_1.STL</uri>
                        <scale>0.001 0.001 0.001</scale>
                    </mesh>
                </geometry>
            </visual>
        </link>

        <link name="right_rocker">
            <gravity>false</gravity>
            <pose>-0.25 -0.7 -0.4 1.571 0 1.571</pose>
            <inertial>
                <pose>0.7 0.35 0 0 0 0</pose>
            </inertial>
            <collision name="left_rocker_collision">
                <geometry>
                    <mesh>
                        <uri>model://rover/meshes/Rocker_Type_1.STL</uri>
                        <scale>0.001 0.001 0.001</scale>
                    </mesh>
                </geometry>
            </collision>
            <visual name="left_rocker_visual">
                <geometry>
                    <mesh>
                        <uri>model://rover/meshes/Rocker_Type_1.STL</uri>
                        <scale>0.001 0.001 0.001</scale>
                    </mesh>
                </geometry>
            </visual>
        </link>

        <link name="right_bogie">
            <gravity>false</gravity>
            <pose>-1.08 -0.6 -0.73 1.571 0 1.571</pose>
            <inertial>
                <pose>0.745 0.475 0.83 0 0 0</pose>
            </inertial>
            <collision name="right_bogie_collision">
                <geometry>
                    <mesh>
                        <uri>model://rover/meshes/Bogie_Type_1.STL</uri>
                        <scale>0.001 0.001 0.001</scale>
                    </mesh>
                </geometry>
            </collision>
            <visual name="right_bogie_visual">
                <geometry>
                    <mesh>
                        <uri>model://rover/meshes/Bogie_Type_1.STL</uri>
                        <scale>0.001 0.001 0.001</scale>
                    </mesh>
                </geometry>
            </visual>
        </link>

        <link name="left_bogie">
            <gravity>false</gravity>
            <pose>-0.58 -0.6 -0.73 1.571 0 1.571</pose>
            <inertial>
                <pose>0.745 0.475 0.83 0 0 0</pose>
            </inertial>
            <collision name="right_bogie_collision">
                <geometry>
                    <mesh>
                        <uri>model://rover/meshes/Bogie_Type_1.STL</uri>
                        <scale>0.001 0.001 0.001</scale>
                    </mesh>
                </geometry>
            </collision>
            <visual name="right_bogie_visual">
                <geometry>
                    <mesh>
                        <uri>model://rover/meshes/Bogie_Type_1.STL</uri>
                        <scale>0.001 0.001 0.001</scale>
                    </mesh>
                </geometry>
            </visual>
        </link>

        <joint name="left_rocker_joint" type="revolute">
            <pose>0.7 0.35 0 0 0 0</pose>
            <child>left_rocker</child>
            <parent>body</parent>
            <axis>
                <limit>
                    <lower>-1.571</lower>
                    <upper>1.571</upper>
                </limit>
                <xyz>0 0 1</xyz>
            </axis>
        </joint>

        <joint name="right_rocker_joint" type="revolute">
            <pose>0.7 0.35 0 0 0 0</pose>
            <child>right_rocker</child>
            <parent>body</parent>
            <axis>
                <limit>
                    <lower>-1.571</lower>
                    <upper>1.571</upper>
                </limit>
                <xyz>0 0 1</xyz>
            </axis>
        </joint>

        <joint name="right_bogie_joint" type="revolute">
            <pose>0.745 0.475 0.83 0 0 0</pose>
            <child>right_bogie</child>
            <parent>right_rocker</parent>
            <axis>
                <limit>
                    <lower>-1.571</lower>
                    <upper>1.571</upper>
                </limit>
                <xyz>0 0 1</xyz>
            </axis>
        </joint>



    </model>
</sdf>